Workbook

Sheet first score
D1: 0 | E1: Item is not covered
D2: 1 | E2: item is present and contains substantial ommisions, inaccuracies, or hallunincations which would effect the scientific integrety if included in SAP
D3: 2 | E3: Item is present and mostly accurate but contains minor inaccuracies or omissions. If left in the SAP, this would not affect integrity.
D4: 3 | E4: Item is accurate, consistent with protocol and makes sense scientifically and contains appropriate level of detail. For statistical analysis this would be sufficient detail for the analysis to be implemented, with no ambiguity.
A10: Our section | B10: Section | C10: Subsection | D10: JAMA SAP # | E10: Description | F10: Notes on scoring | G10: Notes | H10: openAI_gpt5_full | I10: gemini_pro | J10: claude_sonnet | K10: Comment
A11: admin_info | B11: Section 1: Administrative Information | C11: Title and trial registration | D11: 1a | E11: Descriptive title that matches the protocol, with SAP either as a forerunner or subtitle, and trial acronym (if applicable) | H11: 3 | I11: 3 | J11: 3 | K11: Claude_sonnet included the most information (sponsors/ funding /programme management/ and a shortened title).
A12: admin_info | B12: Section 1: Administrative Information | C12: Title and trial registration | D12: 1b | E12: Trial registration number | H12: 3 | I12: 3 | J12: 3
A13: NA | B13: Section 1: Administrative Information | C13: SAP version | D13: 2 | E13: SAP version number with dates
A14: admin_info | B14: Section 1: Administrative Information | C14: Protocol Version | D14: 3 | E14: Reference to version of protocol being used | H14: 3 | I14: 3 | J14: 3
A15: NA | B15: Section 1: Administrative Information | C15: SAP revisions | D15: 4a | E15: SAP revision history
A16: NA | B16: Section 1: Administrative Information | C16: SAP revisions | D16: 4b | E16: Justification for each SAP revision
A17: NA | B17: Section 1: Administrative Information | C17: SAP revisions | D17: 4c | E17: Timing of SAP revisions in relation to interim analyses, etc
A18: admin_info | B18: Section 1: Administrative Information | C18: Roles and responsibility | D18: 5 | E18: Names, affiliations, and roles of SAP contributors | H18: 3 | I18: 3 | J18: 3 | K18: Claude_sonnet included programme management team.
A19: NA | B19: Section 1: Administrative Information | C19: Signatures of: | D19: 6a | E19: Person writing the SAP
A20: NA | B20: Section 1: Administrative Information | C20: Signatures of: | D20: 6b | E20: Senior statistician responsible
A21: NA | B21: Section 1: Administrative Information | C21: Signatures of: | D21: 6c | E21: Chief investigator/clinical lead
A22: introduction | B22: Section 2: Introduction | C22: Background and rationale | D22: 7 | E22: Synopsis of trial background and rationale including a brief description of research question and brief justification for undertaking the trial | H22: 3 | I22: 3 | J22: 3 | K22: Claude_sonnet most closely followed Protocol (I would say used too much information for a SAP). And sometimes quoted studies without providing full information with the extracted information (minor inaccuracy) e.g. MYRIAD study.
A23: introduction | B23: Section 2: Introduction | C23: Objectives | D23: 8 | E23: Description of specific objectives or hypotheses | F23: Accept a vague description as outcomes defined later | H23: 3 | I23: 3 | J23: 3 | K23: Open AI brilliant - picked up on all objectives. Gemini_pro less detail but still good. claude_sonnet good.
A24: study_design | B24: Section 3: Study Methods | C24: Trial design | D24: 9 | E24: Brief description of trial design including type of trial (eg, parallel group, multiarm, crossover, factorial) and allocation ratio and may include brief description of interventions | H24: 3 | I24: 3 | J24: 3 | K24: OpenAI good but not brief. Claude_sonnet the best here - details the internal pilot study etc. Gemini-pro correct but maybe too brief.
A25: study_design | B25: Section 3: Study Methods | C25: Framework | D25: 12 | E25: Superiority, equivalence, or noninferiority hypothesis testing framework, including which comparisons will be presented on this basis | H25: 3 | I25: 3 | J25: 3
A26: randomisation | B26: Section 3: Study Methods | C26: Randomisation | D26: 10 | E26: Randomization details, eg, whether any minimization or stratification occurred (including stratifying factors used or the location of that information if it is not held within the SAP) | H26: 3 | I26: 3 | J26: 3 | K26: claude_sonnet discusses that the remote site will accomodate people who prefer remote delivery (this isn't the case)
A27: sample_size | B27: Section 3: Study Methods | C27: Sample size | D27: 11 | E27: Full sample size calculation or reference to sample size calculation in protocol (instead of replication in SAP) | H27: 3 | I27: 3 | J27: 3 | K27: OpenAI said ANCOVA model used (instead of AUC model). Gemini-pro slightly lacking detail. Claude_sonnet great.
A28: interim_analysis | B28: Section 3: Study Methods | C28: Statistical interim analyses and stopping guidance | D28: 13a | E28: Information on interim analyses specifying what interim analyses will be carried out and listing of time points | H28: 3 | I28: 3 | J28: 3 | K28: Although - no details of pilot will be put in SAP/no interim analysis - so did produce this section unnecessarily.
A29: interim_analysis | B29: Section 3: Study Methods | C29: Statistical interim analyses and stopping guidance | D29: 13b | E29: Any planned adjustment of the significance level due to interim analysis | F29: If no interim analysis score 3 if this item is ommited. If there is a formal interim analysis and adjustment of the significance level, score item as 1 if it says an alpha of 0.05 will be used with 95% confidence intervals, even if it goes on to give the correct significance levels. | H29: 3 | I29: 3 | J29: 3
A30: interim_analysis | B30: Section 3: Study Methods | C30: Statistical interim analyses and stopping guidance | D30: 13c | E30: Details of guidelines for stopping the trial early | H30: 3 | I30: 3 | J30: 3
A31: timing | B31: Section 3: Study Methods | C31: Timing of final analysis | D31: 14 | E31: Timing of final analysis, eg, all outcomes analyzed collectively or timing stratified by planned length of follow-up | H31: 3 | I31: 2 | J31: 3 | K31: gemini_pro low on info. claude_sonnet best.
A32: timing | B32: Section 3: Study Methods | C32: Timing of outcome assessments | D32: 15 | E32: Time points at which the outcomes are measured including visit “windows” | F32: Score 2 if missing visit windows, that are mentioned in the protocol | H32: 3 | I32: 3 | J32: 3
A33: analysis_considerations | B33: Section 4: Statistical Principles | C33: Confidence intervals and P values | D33: 16 | E33: Level of statistical significance | H33: 3 | I33: 3 | J33: 3
A34: analysis_considerations | B34: Section 4: Statistical Principles | C34: Confidence intervals and P values | D34: 17 | E34: Description and rationale for any adjustment for multiplicity and, if so, detailing how the type 1 error is to be controlled | H34: 3 | I34: 3 | J34: 3 | K34: (no adjustments)
A35: analysis_considerations | B35: Section 4: Statistical Principles | C35: Confidence intervals and P values | D35: 18 | E35: Confidence intervals to be reported | H35: 3 | I35: 3 | J35: 3
A36: analysis_considerations | B36: Section 4: Statistical Principles | C36: Adherence and protocol deviations | D36: 19a | E36: Definition of adherence to the intervention and how this is assessed including extent of exposure | H36: 3 | I36: 3 | J36: 3
A37: analysis_considerations | B37: Section 4: Statistical Principles | C37: Adherence and protocol deviations | D37: 19b | E37: Description of how adherence to the intervention will be presented | H37: 3 | I37: 1 | J37: 3 | K37: slightly off the mark for openAI and claude_sonnet
A38: analysis_considerations | B38: Section 4: Statistical Principles | C38: Adherence and protocol deviations | D38: 19c | E38: Definition of protocol deviations for the trial | F38: If protocol deviations are not given in the protocol, the ideal response would be “No protocol deviations are defined in the protocol” or similar. If a sensible answer is given with details that are not given in the protocol, score 2. If specific protocol deviations are mentioned in the protocol, and not covered by the AI in the SAP score 1. | H38: 3 | I38: 2 | J38: 3
A39: analysis_considerations | B39: Section 4: Statistical Principles | C39: Adherence and protocol deviations | D39: 19d | E39: Description of which protocol deviations will be summarized | F39: Score 3 if it says it will describe the protocol deviations it has defined descriptively by arm even if the answer to 19c is not perfect. | H39: 3 | I39: 2 | J39: 3 | K39: Minor deviations/major not covered by gemini pro
A40: trial_population | B40: Section 4: Statistical Principles | C40: Analysis populations | D40: 20 | E40: Definition of analysis populations, eg, intention to treat, per protocol, complete case, safety | F40: If the analysis populations are defined that are not the protocol, then score as a 2. E.g., if a per-protocol population or a safety population is defined that is not in the protocol, then score a 2. | H40: 3 | I40: 3 | J40: 3 | K40: not mentioned for those scored 0
A41: trial_population | B41: Section 5: Trial Population | C41: Screening data | D41: 21 | E41: Reporting of screening data (if collected) to describe representativeness of trial sample | H41: 3 | I41: 3 | J41: 3
A42: trial_population | B42: Section 5: Trial Population | D42: 22 | E42: Summary of eligibility criteria | F42: score 2 if missing inclusion/exclusion criteria | H42: 3 | I42: 3 | J42: 3
A43: trial_population | B43: Section 5: Trial Population | C43: Recruitment | D43: 23 | E43: Information to be included in the CONSORT flow diagram | H43: 2 | I43: 2 | J43: 2 | K43: OpenAI says CONSORT to include adherence, but does include number of people contacted, and others dont.
A44: trial_population | B44: Section 5: Trial Population | C44: Withdrawal/follow-up | D44: 24a | E44: Level of withdrawal, eg, from intervention and/or from follow-up | H44: 3 | I44: 2 | J44: 3 | K44: OpenAI - different withdrawals defined that are not in protocol - but not necessarily wrong. gemini pro - no active withdrawal vs loss to follow up distinction.
A45: trial_population | B45: Section 5: Trial Population | C45: Withdrawal/follow-up | D45: 24b | E45: Timing of withdrawal/lost to follow-up data | H45: 2 | I45: 2 | J45: 2 | K45: withdrawal will actually be measured prior to T1, and between T1 and T2. None of them got this.
...

Sheet second score
D1: 0 | E1: Item is not covered
D2: 1 | E2: item is present and contains substantial ommisions, inaccuracies, or hallunincations which would effect the scientific integrety if included in SAP
D3: 2 | E3: Item is present and mostly accurate but contains minor inaccuracies or omissions. If left in the SAP, this would not affect integrity.
D4: 3 | E4: Item is accurate, consistent with protocol and makes sense scientifically and contains appropriate level of detail. For statistical analysis this would be sufficient detail for the analysis to be implemented, with no ambiguity.
A10: Our section | B10: Section | C10: Subsection | D10: JAMA SAP # | E10: Description | F10: Notes on scoring | G10: Notes | H10: openAI_gpt5_full | I10: gemini_pro | J10: claude_sonnet | K10: Comment
A11: admin_info | B11: Section 1: Administrative Information | C11: Title and trial registration | D11: 1a | E11: Descriptive title that matches the protocol, with SAP either as a forerunner or subtitle, and trial acronym (if applicable) | H11: 3 | I11: 3 | J11: 3
A12: admin_info | B12: Section 1: Administrative Information | C12: Title and trial registration | D12: 1b | E12: Trial registration number | H12: 3 | I12: 3 | J12: 3
A13: NA | B13: Section 1: Administrative Information | C13: SAP version | D13: 2 | E13: SAP version number with dates
A14: admin_info | B14: Section 1: Administrative Information | C14: Protocol Version | D14: 3 | E14: Reference to version of protocol being used | H14: 3 | I14: 3 | J14: 3
A15: NA | B15: Section 1: Administrative Information | C15: SAP revisions | D15: 4a | E15: SAP revision history
A16: NA | B16: Section 1: Administrative Information | C16: SAP revisions | D16: 4b | E16: Justification for each SAP revision
A17: NA | B17: Section 1: Administrative Information | C17: SAP revisions | D17: 4c | E17: Timing of SAP revisions in relation to interim analyses, etc
A18: admin_info | B18: Section 1: Administrative Information | C18: Roles and responsibility | D18: 5 | E18: Names, affiliations, and roles of SAP contributors | H18: 3 | I18: 3 | J18: 3
A19: NA | B19: Section 1: Administrative Information | C19: Signatures of: | D19: 6a | E19: Person writing the SAP
A20: NA | B20: Section 1: Administrative Information | C20: Signatures of: | D20: 6b | E20: Senior statistician responsible
A21: NA | B21: Section 1: Administrative Information | C21: Signatures of: | D21: 6c | E21: Chief investigator/clinical lead
A22: introduction | B22: Section 2: Introduction | C22: Background and rationale | D22: 7 | E22: Synopsis of trial background and rationale including a brief description of research question and brief justification for undertaking the trial | H22: 3 | I22: 3 | J22: 3 | K22: claude (verbose)
A23: introduction | B23: Section 2: Introduction | C23: Objectives | D23: 8 | E23: Description of specific objectives or hypotheses | F23: Accept a vague description as outcomes defined later | H23: 3 | I23: 3 | J23: 3
A24: study_design | B24: Section 3: Study Methods | C24: Trial design | D24: 9 | E24: Brief description of trial design including type of trial (eg, parallel group, multiarm, crossover, factorial) and allocation ratio and may include brief description of interventions | H24: 3 | I24: 3 | J24: 3
A25: study_design | B25: Section 3: Study Methods | C25: Framework | D25: 12 | E25: Superiority, equivalence, or noninferiority hypothesis testing framework, including which comparisons will be presented on this basis | H25: 3 | I25: 3 | J25: 3
A26: randomisation | B26: Section 3: Study Methods | C26: Randomisation | D26: 10 | E26: Randomization details, eg, whether any minimization or stratification occurred (including stratifying factors used or the location of that information if it is not held within the SAP) | H26: 3 | I26: 3 | J26: 3 | K26: The remote site to accompodate people who prefer remote treatment is correct according to the protocol.
A27: sample_size | B27: Section 3: Study Methods | C27: Sample size | D27: 11 | E27: Full sample size calculation or reference to sample size calculation in protocol (instead of replication in SAP) | H27: 3 | I27: 3 | J27: 3 | K27: They did not explicitly model the AUC when calculating the sample size. they used a simplified t-test approach based on a single time point (or an average of a couple of points).
A28: interim_analysis | B28: Section 3: Study Methods | C28: Statistical interim analyses and stopping guidance | D28: 13a | E28: Information on interim analyses specifying what interim analyses will be carried out and listing of time points | H28: 3 | I28: 3 | J28: 3
A29: interim_analysis | B29: Section 3: Study Methods | C29: Statistical interim analyses and stopping guidance | D29: 13b | E29: Any planned adjustment of the significance level due to interim analysis | F29: If no interim analysis score 3 if this item is ommited. If there is a formal interim analysis and adjustment of the significance level, score item as 1 if it says an alpha of 0.05 will be used with 95% confidence intervals, even if it goes on to give the correct significance levels. | H29: 3 | I29: 3 | J29: 3
A30: interim_analysis | B30: Section 3: Study Methods | C30: Statistical interim analyses and stopping guidance | D30: 13c | E30: Details of guidelines for stopping the trial early | H30: 3 | I30: 3 | J30: 3
A31: timing | B31: Section 3: Study Methods | C31: Timing of final analysis | D31: 14 | E31: Timing of final analysis, eg, all outcomes analyzed collectively or timing stratified by planned length of follow-up | H31: 3 | I31: 2 | J31: 3 | K31: gemni is too berif so it missed some infomation about the primary and secondary outcome.
A32: timing | B32: Section 3: Study Methods | C32: Timing of outcome assessments | D32: 15 | E32: Time points at which the outcomes are measured including visit “windows” | F32: Score 2 if missing visit windows, that are mentioned in the protocol | H32: 3 | I32: 3 | J32: 3 | K32: Gemini said nothing about the visit window.
A33: analysis_considerations | B33: Section 4: Statistical Principles | C33: Confidence intervals and P values | D33: 16 | E33: Level of statistical significance | H33: 3 | I33: 3 | J33: 3
A34: analysis_considerations | B34: Section 4: Statistical Principles | C34: Confidence intervals and P values | D34: 17 | E34: Description and rationale for any adjustment for multiplicity and, if so, detailing how the type 1 error is to be controlled | H34: 3 | I34: 3 | J34: 3
A35: analysis_considerations | B35: Section 4: Statistical Principles | C35: Confidence intervals and P values | D35: 18 | E35: Confidence intervals to be reported | H35: 3 | I35: 3 | J35: 3
A36: analysis_considerations | B36: Section 4: Statistical Principles | C36: Adherence and protocol deviations | D36: 19a | E36: Definition of adherence to the intervention and how this is assessed including extent of exposure | H36: 3 | I36: 3 | J36: 3
A37: analysis_considerations | B37: Section 4: Statistical Principles | C37: Adherence and protocol deviations | D37: 19b | E37: Description of how adherence to the intervention will be presented | H37: 3 | I37: 1 | J37: 3
A38: analysis_considerations | B38: Section 4: Statistical Principles | C38: Adherence and protocol deviations | D38: 19c | E38: Definition of protocol deviations for the trial | F38: If protocol deviations are not given in the protocol, the ideal response would be “No protocol deviations are defined in the protocol” or similar. If a sensible answer is given with details that are not given in the protocol, score 2. If specific protocol deviations are mentioned in the protocol, and not covered by the AI in the SAP score 1. | H38: 3 | I38: 2 | J38: 3 | K38: gemini: nothing said about the minor protocol violation.
A39: analysis_considerations | B39: Section 4: Statistical Principles | C39: Adherence and protocol deviations | D39: 19d | E39: Description of which protocol deviations will be summarized | F39: Score 3 if it says it will describe the protocol deviations it has defined descriptively by arm even if the answer to 19c is not perfect. | H39: 3 | I39: 2 | J39: 3
A40: trial_population | B40: Section 4: Statistical Principles | C40: Analysis populations | D40: 20 | E40: Definition of analysis populations, eg, intention to treat, per protocol, complete case, safety | F40: If the analysis populations are defined that are not the protocol, then score as a 2. E.g., if a per-protocol population or a safety population is defined that is not in the protocol, then score a 2. | H40: 3 | I40: 3 | J40: 3 | K40: i don't understand the first score comment (not mentioned for those scored 0) - to discuss and reconcile
A41: trial_population | B41: Section 5: Trial Population | C41: Screening data | D41: 21 | E41: Reporting of screening data (if collected) to describe representativeness of trial sample | H41: 3 | I41: 3 | J41: 3
A42: trial_population | B42: Section 5: Trial Population | D42: 22 | E42: Summary of eligibility criteria | F42: score 2 if missing inclusion/exclusion criteria | H42: 3 | I42: 3 | J42: 3
A43: trial_population | B43: Section 5: Trial Population | C43: Recruitment | D43: 23 | E43: Information to be included in the CONSORT flow diagram | H43: 2 | I43: 2 | J43: 2 | K43: OpenAI: included too many information in CONSORT diagram, I don't think this is a standard. Claude said... as well as completion rates for the fortnightly SMFQ and PHQ-8 measures throughout the 12-month follow-up period. I think preenthing data completion every two weeks for 12 month is not something we do normally in a CONSORT
A44: trial_population | B44: Section 5: Trial Population | C44: Withdrawal/follow-up | D44: 24a | E44: Level of withdrawal, eg, from intervention and/or from follow-up | H44: 3 | I44: 2 | J44: 3
A45: trial_population | B45: Section 5: Trial Population | C45: Withdrawal/follow-up | D45: 24b | E45: Timing of withdrawal/lost to follow-up data | H45: 2 | I45: 2 | J45: 2
...

Sheet validation
D1: 0 | E1: Item is not covered
D2: 1 | E2: item is present and contains substantial ommisions, inaccuracies, or hallunincations which would effect the scientific integrety if included in SAP
D3: 2 | E3: Item is present and mostly accurate but contains minor inaccuracies or omissions. If left in the SAP, this would not affect integrity.
D4: 3 | E4: Item is accurate, consistent with protocol and makes sense scientifically and contains appropriate level of detail. For statistical analysis this would be sufficient detail for the analysis to be implemented, with no ambiguity.
A10: Our section | B10: Section | C10: Subsection | D10: JAMA SAP # | E10: Description | F10: Notes on scoring | G10: Notes | H10: openAI_gpt5_full | I10: openAI_full | J10: gemini_pro | K10: claude_sonnet | L10: Comment | M10: Match full | N10: Average Full 1 | O10: Average Full 2
A11: admin_info | B11: Section 1: Administrative Information | C11: Title and trial registration | D11: 1a | E11: Descriptive title that matches the protocol, with SAP either as a forerunner or subtitle, and trial acronym (if applicable) | I11: ='first score'!H11='second score'!H11 -> TRUE | J11: ='first score'!I11='second score'!I11 -> TRUE | K11: ='first score'!J11='second score'!J11 -> TRUE | M11: =AND(I11:K11) -> TRUE | N11: =AVERAGE('first score'!H11:'first score'!J11) -> 3 | O11: =AVERAGE('second score'!H11:'second score'!J11) -> 3
A12: admin_info | B12: Section 1: Administrative Information | C12: Title and trial registration | D12: 1b | E12: Trial registration number | I12: ='first score'!H12='second score'!H12 -> TRUE | J12: ='first score'!I12='second score'!I12 -> TRUE | K12: ='first score'!J12='second score'!J12 -> TRUE | M12: =AND(I12:K12) -> TRUE | N12: =AVERAGE('first score'!H12:'first score'!J12) -> 3 | O12: =AVERAGE('second score'!H12:'second score'!J12) -> 3
A13: NA | B13: Section 1: Administrative Information | C13: SAP version | D13: 2 | E13: SAP version number with dates
A14: admin_info | B14: Section 1: Administrative Information | C14: Protocol Version | D14: 3 | E14: Reference to version of protocol being used | I14: ='first score'!H14='second score'!H14 -> TRUE | J14: ='first score'!I14='second score'!I14 -> TRUE | K14: ='first score'!J14='second score'!J14 -> TRUE | M14: =AND(I14:K14) -> TRUE | N14: =AVERAGE('first score'!H14:'first score'!J14) -> 3 | O14: =AVERAGE('second score'!H14:'second score'!J14) -> 3
A15: NA | B15: Section 1: Administrative Information | C15: SAP revisions | D15: 4a | E15: SAP revision history
A16: NA | B16: Section 1: Administrative Information | C16: SAP revisions | D16: 4b | E16: Justification for each SAP revision
A17: NA | B17: Section 1: Administrative Information | C17: SAP revisions | D17: 4c | E17: Timing of SAP revisions in relation to interim analyses, etc
A18: admin_info | B18: Section 1: Administrative Information | C18: Roles and responsibility | D18: 5 | E18: Names, affiliations, and roles of SAP contributors | I18: ='first score'!H18='second score'!H18 -> TRUE | J18: ='first score'!I18='second score'!I18 -> TRUE | K18: ='first score'!J18='second score'!J18 -> TRUE | M18: =AND(I18:K18) -> TRUE | N18: =AVERAGE('first score'!H18:'first score'!J18) -> 3 | O18: =AVERAGE('second score'!H18:'second score'!J18) -> 3
A19: NA | B19: Section 1: Administrative Information | C19: Signatures of: | D19: 6a | E19: Person writing the SAP
A20: NA | B20: Section 1: Administrative Information | C20: Signatures of: | D20: 6b | E20: Senior statistician responsible
A21: NA | B21: Section 1: Administrative Information | C21: Signatures of: | D21: 6c | E21: Chief investigator/clinical lead
A22: introduction | B22: Section 2: Introduction | C22: Background and rationale | D22: 7 | E22: Synopsis of trial background and rationale including a brief description of research question and brief justification for undertaking the trial | I22: ='first score'!H22='second score'!H22 -> TRUE | J22: ='first score'!I22='second score'!I22 -> TRUE | K22: ='first score'!J22='second score'!J22 -> TRUE | M22: =AND(I22:K22) -> TRUE | N22: =AVERAGE('first score'!H22:'first score'!J22) -> 3 | O22: =AVERAGE('second score'!H22:'second score'!J22) -> 3
A23: introduction | B23: Section 2: Introduction | C23: Objectives | D23: 8 | E23: Description of specific objectives or hypotheses | F23: Accept a vague description as outcomes defined later | I23: ='first score'!H23='second score'!H23 -> TRUE | J23: ='first score'!I23='second score'!I23 -> TRUE | K23: ='first score'!J23='second score'!J23 -> TRUE | M23: =AND(I23:K23) -> TRUE | N23: =AVERAGE('first score'!H23:'first score'!J23) -> 3 | O23: =AVERAGE('second score'!H23:'second score'!J23) -> 3
A24: study_design | B24: Section 3: Study Methods | C24: Trial design | D24: 9 | E24: Brief description of trial design including type of trial (eg, parallel group, multiarm, crossover, factorial) and allocation ratio and may include brief description of interventions | I24: ='first score'!H24='second score'!H24 -> TRUE | J24: ='first score'!I24='second score'!I24 -> TRUE | K24: ='first score'!J24='second score'!J24 -> TRUE | M24: =AND(I24:K24) -> TRUE | N24: =AVERAGE('first score'!H24:'first score'!J24) -> 3 | O24: =AVERAGE('second score'!H24:'second score'!J24) -> 3
A25: study_design | B25: Section 3: Study Methods | C25: Framework | D25: 12 | E25: Superiority, equivalence, or noninferiority hypothesis testing framework, including which comparisons will be presented on this basis | I25: ='first score'!H25='second score'!H25 -> TRUE | J25: ='first score'!I25='second score'!I25 -> TRUE | K25: ='first score'!J25='second score'!J25 -> TRUE | M25: =AND(I25:K25) -> TRUE | N25: =AVERAGE('first score'!H25:'first score'!J25) -> 3 | O25: =AVERAGE('second score'!H25:'second score'!J25) -> 3
A26: randomisation | B26: Section 3: Study Methods | C26: Randomisation | D26: 10 | E26: Randomization details, eg, whether any minimization or stratification occurred (including stratifying factors used or the location of that information if it is not held within the SAP) | I26: ='first score'!H26='second score'!H26 -> TRUE | J26: ='first score'!I26='second score'!I26 -> TRUE | K26: ='first score'!J26='second score'!J26 -> TRUE | M26: =AND(I26:K26) -> TRUE | N26: =AVERAGE('first score'!H26:'first score'!J26) -> 3 | O26: =AVERAGE('second score'!H26:'second score'!J26) -> 3
A27: sample_size | B27: Section 3: Study Methods | C27: Sample size | D27: 11 | E27: Full sample size calculation or reference to sample size calculation in protocol (instead of replication in SAP) | I27: ='first score'!H27='second score'!H27 -> TRUE | J27: ='first score'!I27='second score'!I27 -> TRUE | K27: ='first score'!J27='second score'!J27 -> TRUE | M27: =AND(I27:K27) -> TRUE | N27: =AVERAGE('first score'!H27:'first score'!J27) -> 3 | O27: =AVERAGE('second score'!H27:'second score'!J27) -> 3
A28: interim_analysis | B28: Section 3: Study Methods | C28: Statistical interim analyses and stopping guidance | D28: 13a | E28: Information on interim analyses specifying what interim analyses will be carried out and listing of time points | I28: ='first score'!H28='second score'!H28 -> TRUE | J28: ='first score'!I28='second score'!I28 -> TRUE | K28: ='first score'!J28='second score'!J28 -> TRUE | M28: =AND(I28:K28) -> TRUE | N28: =AVERAGE('first score'!H28:'first score'!J28) -> 3 | O28: =AVERAGE('second score'!H28:'second score'!J28) -> 3
A29: interim_analysis | B29: Section 3: Study Methods | C29: Statistical interim analyses and stopping guidance | D29: 13b | E29: Any planned adjustment of the significance level due to interim analysis | F29: If no interim analysis score 3 if this item is ommited. If there is a formal interim analysis and adjustment of the significance level, score item as 1 if it says an alpha of 0.05 will be used with 95% confidence intervals, even if it goes on to give the correct significance levels. | I29: ='first score'!H29='second score'!H29 -> TRUE | J29: ='first score'!I29='second score'!I29 -> TRUE | K29: ='first score'!J29='second score'!J29 -> TRUE | M29: =AND(I29:K29) -> TRUE | N29: =AVERAGE('first score'!H29:'first score'!J29) -> 3 | O29: =AVERAGE('second score'!H29:'second score'!J29) -> 3
A30: interim_analysis | B30: Section 3: Study Methods | C30: Statistical interim analyses and stopping guidance | D30: 13c | E30: Details of guidelines for stopping the trial early | I30: ='first score'!H30='second score'!H30 -> TRUE | J30: ='first score'!I30='second score'!I30 -> TRUE | K30: ='first score'!J30='second score'!J30 -> TRUE | M30: =AND(I30:K30) -> TRUE | N30: =AVERAGE('first score'!H30:'first score'!J30) -> 3 | O30: =AVERAGE('second score'!H30:'second score'!J30) -> 3
A31: timing | B31: Section 3: Study Methods | C31: Timing of final analysis | D31: 14 | E31: Timing of final analysis, eg, all outcomes analyzed collectively or timing stratified by planned length of follow-up | I31: ='first score'!H31='second score'!H31 -> TRUE | J31: ='first score'!I31='second score'!I31 -> TRUE | K31: ='first score'!J31='second score'!J31 -> TRUE | M31: =AND(I31:K31) -> TRUE | N31: =AVERAGE('first score'!H31:'first score'!J31) -> 2.6666667 | O31: =AVERAGE('second score'!H31:'second score'!J31) -> 2.6666667
A32: timing | B32: Section 3: Study Methods | C32: Timing of outcome assessments | D32: 15 | E32: Time points at which the outcomes are measured including visit “windows” | F32: Score 2 if missing visit windows, that are mentioned in the protocol | I32: ='first score'!H32='second score'!H32 -> TRUE | J32: ='first score'!I32='second score'!I32 -> TRUE | K32: ='first score'!J32='second score'!J32 -> TRUE | M32: =AND(I32:K32) -> TRUE | N32: =AVERAGE('first score'!H32:'first score'!J32) -> 3 | O32: =AVERAGE('second score'!H32:'second score'!J32) -> 3
A33: analysis_considerations | B33: Section 4: Statistical Principles | C33: Confidence intervals and P values | D33: 16 | E33: Level of statistical significance | I33: ='first score'!H33='second score'!H33 -> TRUE | J33: ='first score'!I33='second score'!I33 -> TRUE | K33: ='first score'!J33='second score'!J33 -> TRUE | M33: =AND(I33:K33) -> TRUE | N33: =AVERAGE('first score'!H33:'first score'!J33) -> 3 | O33: =AVERAGE('second score'!H33:'second score'!J33) -> 3
A34: analysis_considerations | B34: Section 4: Statistical Principles | C34: Confidence intervals and P values | D34: 17 | E34: Description and rationale for any adjustment for multiplicity and, if so, detailing how the type 1 error is to be controlled | I34: ='first score'!H34='second score'!H34 -> TRUE | J34: ='first score'!I34='second score'!I34 -> TRUE | K34: ='first score'!J34='second score'!J34 -> TRUE | M34: =AND(I34:K34) -> TRUE | N34: =AVERAGE('first score'!H34:'first score'!J34) -> 3 | O34: =AVERAGE('second score'!H34:'second score'!J34) -> 3
A35: analysis_considerations | B35: Section 4: Statistical Principles | C35: Confidence intervals and P values | D35: 18 | E35: Confidence intervals to be reported | I35: ='first score'!H35='second score'!H35 -> TRUE | J35: ='first score'!I35='second score'!I35 -> TRUE | K35: ='first score'!J35='second score'!J35 -> TRUE | M35: =AND(I35:K35) -> TRUE | N35: =AVERAGE('first score'!H35:'first score'!J35) -> 3 | O35: =AVERAGE('second score'!H35:'second score'!J35) -> 3
A36: analysis_considerations | B36: Section 4: Statistical Principles | C36: Adherence and protocol deviations | D36: 19a | E36: Definition of adherence to the intervention and how this is assessed including extent of exposure | I36: ='first score'!H36='second score'!H36 -> TRUE | J36: ='first score'!I36='second score'!I36 -> TRUE | K36: ='first score'!J36='second score'!J36 -> TRUE | M36: =AND(I36:K36) -> TRUE | N36: =AVERAGE('first score'!H36:'first score'!J36) -> 3 | O36: =AVERAGE('second score'!H36:'second score'!J36) -> 3
A37: analysis_considerations | B37: Section 4: Statistical Principles | C37: Adherence and protocol deviations | D37: 19b | E37: Description of how adherence to the intervention will be presented | I37: ='first score'!H37='second score'!H37 -> TRUE | J37: ='first score'!I37='second score'!I37 -> TRUE | K37: ='first score'!J37='second score'!J37 -> TRUE | M37: =AND(I37:K37) -> TRUE | N37: =AVERAGE('first score'!H37:'first score'!J37) -> 2.3333333 | O37: =AVERAGE('second score'!H37:'second score'!J37) -> 2.3333333
A38: analysis_considerations | B38: Section 4: Statistical Principles | C38: Adherence and protocol deviations | D38: 19c | E38: Definition of protocol deviations for the trial | F38: If protocol deviations are not given in the protocol, the ideal response would be “No protocol deviations are defined in the protocol” or similar. If a sensible answer is given with details that are not given in the protocol, score 2. If specific protocol deviations are mentioned in the protocol, and not covered by the AI in the SAP score 1. | I38: ='first score'!H38='second score'!H38 -> TRUE | J38: ='first score'!I38='second score'!I38 -> TRUE | K38: ='first score'!J38='second score'!J38 -> TRUE | M38: =AND(I38:K38) -> TRUE | N38: =AVERAGE('first score'!H38:'first score'!J38) -> 2.6666667 | O38: =AVERAGE('second score'!H38:'second score'!J38) -> 2.6666667
A39: analysis_considerations | B39: Section 4: Statistical Principles | C39: Adherence and protocol deviations | D39: 19d | E39: Description of which protocol deviations will be summarized | F39: Score 3 if it says it will describe the protocol deviations it has defined descriptively by arm even if the answer to 19c is not perfect. | I39: ='first score'!H39='second score'!H39 -> TRUE | J39: ='first score'!I39='second score'!I39 -> TRUE | K39: ='first score'!J39='second score'!J39 -> TRUE | M39: =AND(I39:K39) -> TRUE | N39: =AVERAGE('first score'!H39:'first score'!J39) -> 2.6666667 | O39: =AVERAGE('second score'!H39:'second score'!J39) -> 2.6666667
A40: trial_population | B40: Section 4: Statistical Principles | C40: Analysis populations | D40: 20 | E40: Definition of analysis populations, eg, intention to treat, per protocol, complete case, safety | F40: If the analysis populations are defined that are not the protocol, then score as a 2. E.g., if a per-protocol population or a safety population is defined that is not in the protocol, then score a 2. | I40: ='first score'!H40='second score'!H40 -> TRUE | J40: ='first score'!I40='second score'!I40 -> TRUE | K40: ='first score'!J40='second score'!J40 -> TRUE | M40: =AND(I40:K40) -> TRUE | N40: =AVERAGE('first score'!H40:'first score'!J40) -> 3 | O40: =AVERAGE('second score'!H40:'second score'!J40) -> 3
A41: trial_population | B41: Section 5: Trial Population | C41: Screening data | D41: 21 | E41: Reporting of screening data (if collected) to describe representativeness of trial sample | I41: ='first score'!H41='second score'!H41 -> TRUE | J41: ='first score'!I41='second score'!I41 -> TRUE | K41: ='first score'!J41='second score'!J41 -> TRUE | M41: =AND(I41:K41) -> TRUE | N41: =AVERAGE('first score'!H41:'first score'!J41) -> 3 | O41: =AVERAGE('second score'!H41:'second score'!J41) -> 3
A42: trial_population | B42: Section 5: Trial Population | D42: 22 | E42: Summary of eligibility criteria | F42: score 2 if missing inclusion/exclusion criteria | I42: ='first score'!H42='second score'!H42 -> TRUE | J42: ='first score'!I42='second score'!I42 -> TRUE | K42: ='first score'!J42='second score'!J42 -> TRUE | M42: =AND(I42:K42) -> TRUE | N42: =AVERAGE('first score'!H42:'first score'!J42) -> 3 | O42: =AVERAGE('second score'!H42:'second score'!J42) -> 3
A43: trial_population | B43: Section 5: Trial Population | C43: Recruitment | D43: 23 | E43: Information to be included in the CONSORT flow diagram | I43: ='first score'!H43='second score'!H43 -> TRUE | J43: ='first score'!I43='second score'!I43 -> TRUE | K43: ='first score'!J43='second score'!J43 -> TRUE | M43: =AND(I43:K43) -> TRUE | N43: =AVERAGE('first score'!H43:'first score'!J43) -> 2 | O43: =AVERAGE('second score'!H43:'second score'!J43) -> 2
A44: trial_population | B44: Section 5: Trial Population | C44: Withdrawal/follow-up | D44: 24a | E44: Level of withdrawal, eg, from intervention and/or from follow-up | I44: ='first score'!H44='second score'!H44 -> TRUE | J44: ='first score'!I44='second score'!I44 -> TRUE | K44: ='first score'!J44='second score'!J44 -> TRUE | M44: =AND(I44:K44) -> TRUE | N44: =AVERAGE('first score'!H44:'first score'!J44) -> 2.6666667 | O44: =AVERAGE('second score'!H44:'second score'!J44) -> 2.6666667
A45: trial_population | B45: Section 5: Trial Population | C45: Withdrawal/follow-up | D45: 24b | E45: Timing of withdrawal/lost to follow-up data | I45: ='first score'!H45='second score'!H45 -> TRUE | J45: ='first score'!I45='second score'!I45 -> TRUE | K45: ='first score'!J45='second score'!J45 -> TRUE | M45: =AND(I45:K45) -> TRUE | N45: =AVERAGE('first score'!H45:'first score'!J45) -> 2 | O45: =AVERAGE('second score'!H45:'second score'!J45) -> 2
...
